2025-04-13 18:08:04,523 - __main__ - INFO - Starting blog posting test...
2025-04-13 18:08:04,523 - __main__ - INFO - Loaded test post: Test Blog Post Title
2025-04-13 18:08:04,524 - __main__ - INFO - Posting to blog...
2025-04-13 18:08:04,524 - blog_poster - INFO - Posting paper: Test Blog Post Title
2025-04-13 18:08:36,249 - blog_poster - INFO - Successfully saved post to content/posts/2025-04-13_test_paper_001.md
2025-04-13 18:08:36,281 - WDM - INFO - ====== WebDriver manager ======
2025-04-13 18:08:37,214 - WDM - INFO - Get LATEST chromedriver version for google-chrome
2025-04-13 18:08:37,283 - WDM - INFO - Get LATEST chromedriver version for google-chrome
2025-04-13 18:08:37,345 - WDM - INFO - Driver [C:\Users\tpdud\.wdm\drivers\chromedriver\win64\135.0.7049.84\chromedriver-win32/chromedriver.exe] found in cache
2025-04-13 18:08:58,337 - urllib3.connectionpool - WARNING - Retrying (Retry(total=2, connect=None, read=None, redirect=None, status=None)) after connection broken by 'NewConnectionError('<urllib3.connection.HTTPConnection object at 0x000001CA0D6FC610>: Failed to establish a new connection: [WinError 10061] 대상 컴퓨터에서 연결을 거부했으므로 연결하지 못했습니다')': /session/3b217632aca4e419cc1e9282e2428f81/url
2025-04-13 18:09:02,420 - urllib3.connectionpool - WARNING - Retrying (Retry(total=1, connect=None, read=None, redirect=None, status=None)) after connection broken by 'NewConnectionError('<urllib3.connection.HTTPConnection object at 0x000001CA0D6FC7C0>: Failed to establish a new connection: [WinError 10061] 대상 컴퓨터에서 연결을 거부했으므로 연결하지 못했습니다')': /session/3b217632aca4e419cc1e9282e2428f81/url
2025-04-13 18:09:06,495 - urllib3.connectionpool - WARNING - Retrying (Retry(total=0, connect=None, read=None, redirect=None, status=None)) after connection broken by 'NewConnectionError('<urllib3.connection.HTTPConnection object at 0x000001CA0D6FC970>: Failed to establish a new connection: [WinError 10061] 대상 컴퓨터에서 연결을 거부했으므로 연결하지 못했습니다')': /session/3b217632aca4e419cc1e9282e2428f81/url
2025-04-13 18:09:10,577 - blog_poster - ERROR - Login failed: HTTPConnectionPool(host='localhost', port=49400): Max retries exceeded with url: /session/3b217632aca4e419cc1e9282e2428f81/url (Caused by NewConnectionError('<urllib3.connection.HTTPConnection object at 0x000001CA0D6FCB50>: Failed to establish a new connection: [WinError 10061] 대상 컴퓨터에서 연결을 거부했으므로 연결하지 못했습니다'))
Traceback (most recent call last):
  File "C:\Users\tpdud\Anaconda3\envs\blog_AI_News\lib\site-packages\urllib3\connection.py", line 198, in _new_conn
    sock = connection.create_connection(
  File "C:\Users\tpdud\Anaconda3\envs\blog_AI_News\lib\site-packages\urllib3\util\connection.py", line 85, in create_connection
    raise err
  File "C:\Users\tpdud\Anaconda3\envs\blog_AI_News\lib\site-packages\urllib3\util\connection.py", line 73, in create_connection
    sock.connect(sa)
ConnectionRefusedError: [WinError 10061] 대상 컴퓨터에서 연결을 거부했으므로 연결하지 못했습니다

The above exception was the direct cause of the following exception:

Traceback (most recent call last):
  File "C:\Users\tpdud\Anaconda3\envs\blog_AI_News\lib\site-packages\urllib3\connectionpool.py", line 787, in urlopen
    response = self._make_request(
  File "C:\Users\tpdud\Anaconda3\envs\blog_AI_News\lib\site-packages\urllib3\connectionpool.py", line 493, in _make_request
    conn.request(
  File "C:\Users\tpdud\Anaconda3\envs\blog_AI_News\lib\site-packages\urllib3\connection.py", line 445, in request
    self.endheaders()
  File "C:\Users\tpdud\Anaconda3\envs\blog_AI_News\lib\http\client.py", line 1280, in endheaders
    self._send_output(message_body, encode_chunked=encode_chunked)
  File "C:\Users\tpdud\Anaconda3\envs\blog_AI_News\lib\http\client.py", line 1040, in _send_output
    self.send(msg)
  File "C:\Users\tpdud\Anaconda3\envs\blog_AI_News\lib\http\client.py", line 980, in send
    self.connect()
  File "C:\Users\tpdud\Anaconda3\envs\blog_AI_News\lib\site-packages\urllib3\connection.py", line 276, in connect
    self.sock = self._new_conn()
  File "C:\Users\tpdud\Anaconda3\envs\blog_AI_News\lib\site-packages\urllib3\connection.py", line 213, in _new_conn
    raise NewConnectionError(
urllib3.exceptions.NewConnectionError: <urllib3.connection.HTTPConnection object at 0x000001CA0D6FCB50>: Failed to establish a new connection: [WinError 10061] 대상 컴퓨터에서 연결을 거부했으므로 연결하지 못했습니다

The above exception was the direct cause of the following exception:

Traceback (most recent call last):
  File "c:\Users\tpdud\code\blog_AI_News\src\blog_poster.py", line 115, in login
    self.driver.get('https://nid.naver.com/nidlogin.login')
  File "C:\Users\tpdud\Anaconda3\envs\blog_AI_News\lib\site-packages\selenium\webdriver\remote\webdriver.py", line 454, in get
    self.execute(Command.GET, {"url": url})
  File "C:\Users\tpdud\Anaconda3\envs\blog_AI_News\lib\site-packages\selenium\webdriver\remote\webdriver.py", line 427, in execute
    response = self.command_executor.execute(driver_command, params)
  File "C:\Users\tpdud\Anaconda3\envs\blog_AI_News\lib\site-packages\selenium\webdriver\remote\remote_connection.py", line 404, in execute
    return self._request(command_info[0], url, body=data)
  File "C:\Users\tpdud\Anaconda3\envs\blog_AI_News\lib\site-packages\selenium\webdriver\remote\remote_connection.py", line 428, in _request
    response = self._conn.request(method, url, body=body, headers=headers, timeout=self._client_config.timeout)
  File "C:\Users\tpdud\Anaconda3\envs\blog_AI_News\lib\site-packages\urllib3\_request_methods.py", line 143, in request
    return self.request_encode_body(
  File "C:\Users\tpdud\Anaconda3\envs\blog_AI_News\lib\site-packages\urllib3\_request_methods.py", line 278, in request_encode_body
    return self.urlopen(method, url, **extra_kw)
  File "C:\Users\tpdud\Anaconda3\envs\blog_AI_News\lib\site-packages\urllib3\poolmanager.py", line 443, in urlopen
    response = conn.urlopen(method, u.request_uri, **kw)
  File "C:\Users\tpdud\Anaconda3\envs\blog_AI_News\lib\site-packages\urllib3\connectionpool.py", line 871, in urlopen
    return self.urlopen(
  File "C:\Users\tpdud\Anaconda3\envs\blog_AI_News\lib\site-packages\urllib3\connectionpool.py", line 871, in urlopen
    return self.urlopen(
  File "C:\Users\tpdud\Anaconda3\envs\blog_AI_News\lib\site-packages\urllib3\connectionpool.py", line 871, in urlopen
    return self.urlopen(
  File "C:\Users\tpdud\Anaconda3\envs\blog_AI_News\lib\site-packages\urllib3\connectionpool.py", line 841, in urlopen
    retries = retries.increment(
  File "C:\Users\tpdud\Anaconda3\envs\blog_AI_News\lib\site-packages\urllib3\util\retry.py", line 519, in increment
    raise MaxRetryError(_pool, url, reason) from reason  # type: ignore[arg-type]
urllib3.exceptions.MaxRetryError: HTTPConnectionPool(host='localhost', port=49400): Max retries exceeded with url: /session/3b217632aca4e419cc1e9282e2428f81/url (Caused by NewConnectionError('<urllib3.connection.HTTPConnection object at 0x000001CA0D6FCB50>: Failed to establish a new connection: [WinError 10061] 대상 컴퓨터에서 연결을 거부했으므로 연결하지 못했습니다'))
2025-04-13 18:09:10,584 - blog_poster - ERROR - Error posting paper Test Blog Post Title: Failed to login
2025-04-13 18:09:10,585 - __main__ - ERROR - Error during blog posting test: Failed to login
